<?xml version="1.0"?>
<robot xmlns:xacro="http://www.ros.org/wiki/xacro" name="pan_tilt" description="iqr pan tilt">
  <!-- <xacro:include filename = "$(find pan_tilt_description)/urdf/pan_tilt.gazebo.xacro" /> -->
  <xacro:property name="PI" value="3.1415926535897931" />
  <xacro:macro name="pan_tilt" params="parent *origin">
  <xacro:property name="prefix" value="pan_tilt" />
    <joint name="${prefix}_base_joint" type="fixed">
      <xacro:insert_block name="origin" />
      <parent link="${parent}"/>
      <child link="${prefix}_base_link"/>
    </joint>

    <link name="${prefix}_base_link">
      <visual>
        <origin xyz="0 0 0" rpy="0 0 0" />
        <geometry>
          <mesh filename="package://pan_tilt_description/mesh/base.stl" />
        </geometry>
        <material name="">
          <color rgba="0.2 0.2 0.2 1" />
        </material>
      </visual>

      <collision>
        <geometry>
          <mesh filename="package://pan_tilt_description/mesh/base.stl" />
        </geometry>
      </collision>
      
      <inertial>
        <origin xyz="0 0 0" />
        <mass value="0.001" />
        <inertia ixx="0.001" ixy="0.0" ixz="0.0" 
                 iyy="0.001" iyz="0.0" 
                 izz="0.001" />
      </inertial>
    </link>

    <link name="${prefix}_yaw_link">
      <visual>
        <origin xyz="0 0 0" rpy="0 0 0" />
        <geometry>
          <mesh filename="package://pan_tilt_description/mesh/pan.stl" />
        </geometry>
        <material name="">
          <color rgba="0.2 0.2 0.2 1" />
        </material>
      </visual>
      <collision>
        <geometry>
          <mesh filename="package://pan_tilt_description/mesh/pan.stl" />
        </geometry>
      </collision>
      <inertial>
        <origin xyz="0 0 0" />
        <mass value="0.001" />
        <inertia ixx="0.001" ixy="0.0" ixz="-0.0" 
                 iyy="0.001" iyz="0.0" 
                 izz="0.001"  />
      </inertial>
    </link>
    <joint name="${prefix}_yaw_joint" type="revolute">
      <origin xyz="0.0 0.0 0.05455" rpy="0.0 0.0 0.0"/>
      <parent link="${prefix}_base_link"/>
      <child link="${prefix}_yaw_link"/>
      <axis xyz="0 0 1"/>
      <limit lower="-1.04" upper="1.04" effort="0.0" velocity="0.4"/>
      <dynamics damping="0.01" friction="0.0"/>
    </joint>

    <link name="${prefix}_pitch_link">
      <visual>
        <origin xyz="0 0 0" rpy="0 0 0" />
        <geometry>
          <mesh filename="package://pan_tilt_description/mesh/tilt.stl" />
        </geometry>
        <material name="">
          <color rgba="0.2 0.2 0.2 1" />
        </material>
      </visual>
      <collision>
        <geometry>
          <mesh filename="package://pan_tilt_description/mesh/tilt.stl" />
        </geometry>
      </collision>
      <inertial>
        <origin xyz="0 0 0" />
        <mass value="0.001" />
        <inertia ixx="0.001" ixy="0.0" ixz="-0.0" 
                 iyy="0.001" iyz="0.0" 
                 izz="0.001"  />
      </inertial>
    </link>
    <joint name="${prefix}_pitch_joint" type="revolute">
      <origin xyz="0.0 0.0 0.057" rpy="0.0 0.0 0.0"/>
      <parent link="${prefix}_yaw_link"/>
      <child link="${prefix}_pitch_link"/>
      <axis xyz="0 1 0"/>
      <limit lower="-1.04" upper="1.04" effort="0.0" velocity="0.4"/>
      <dynamics damping="0.01" friction="0.0"/>
    </joint>

    <transmission name="tran_pan">
      <type>transmission_interface/SimpleTransmission</type>
      <joint name="${prefix}_yaw_joint">
        <hardwareInterface>hardware_interface/PositionJointInterface</hardwareInterface>
      </joint>
      <actuator name="motor_pan_tilt_yaw">
        <hardwareInterface>hardware_interface/PositionJointInterface</hardwareInterface>
        <mechanicalReduction>1</mechanicalReduction>
      </actuator>
    </transmission>

    <transmission name="tran_tilt">
      <type>transmission_interface/SimpleTransmission</type>
      <joint name="${prefix}_pitch_joint">
        <hardwareInterface>hardware_interface/PositionJointInterface</hardwareInterface>
      </joint>
      <actuator name="motor_pan_tilt_pitch">
        <hardwareInterface>hardware_interface/PositionJointInterface</hardwareInterface>
        <mechanicalReduction>1</mechanicalReduction>
      </actuator>
    </transmission>

    <link name="${prefix}_kinect_surface"/>
    <joint name="${prefix}_kinect_surface_joint" type="fixed">
      <origin xyz="0.0010 0.0077 -0.022" rpy="0 0 0" />
      <parent link="${prefix}_pitch_link"/>
      <child link="${prefix}_kinect_surface"/>
    </joint>
  </xacro:macro>
</robot>
